## 异常

#### 什么是异常

异常是指程序运行时（非编译时）所发生的非正常情况或错误，当程序违反了语义规则时，JVM就会将出现的错误表示为一个异常并抛出。

　　Java语言把异常当做对象来处理，并定义一个基类（java.lang.Throwable）为所有异常类的父类。

　　这些**异常类分为：Error（错误） 和 Exception（异常）**。  
总的来说异常处理机制就是当程序发生异常时，它强制终止程序运行，记录异常信息并将这些信息反馈给我们，由我们来确定是否处理异常。

#### 异常处理

通常情况下，出现异常，异常处理机制是：**抛出异常** 和 **捕获异常**。

**异常抛出**：任何Java代码都可以抛出异常，如：自己编写的代码、来自Java开发环境包中代码，或者Java运行时系统。无论是谁，都可以通过Java的throw语句抛出异常。从方法中抛出的任何异常都必须使用throws子句。  
**异常捕获**：捕捉异常通过try-catch语句或者try-catch-finally语句实现。  
总体来说，Java规定：对于可查异常必须捕捉、或者声明抛出。允许忽略不可查的RuntimeException和Error。

#### throw 和 throws这两个关键字在java中有什么不同

`throw`是抛出单个异常信息或理解为语句抛出异常，可以代替return，一样中断程序。例如：  

```java
public void demo(){
    try{
        ...
    }catch(Exception e){
        throw e;
       	// or
        //throw new Exception("your Exception~");
    }
}
```

`throws`是方法抛出异常，例如：

```java
public void demo throws Exception1,Exception2...(){
    ....
}
```

#### 空指针异常和数组越界异常有什么相同之处

相同之处在于，它们都继承了RuntimeException，是非受查异常。

#### 自定义异常

 [Java](http://lib.csdn.net/base/java)确实给我们提供了非常多的异常，但是异常体系是不可能预见所有的希望加以报告的错误，所以Java允许我们自定义异常来表现程序中可能会遇到的特定问题，总之就是一句话：我们不必拘泥于Java中已有的异常类型。

​    Java自定义异常的使用要经历如下四个步骤：

​    1、定义一个类继承Throwable或其子类。

​    2、添加构造方法(当然也可以不用添加，使用默认构造方法)。

​    3、在某个方法类抛出该异常。

​    4、捕捉该异常。 

```java
/** 自定义异常 继承Exception类 **/  
public class MyException extends Exception{  
    public MyException(){  
          
    }  
      
    public MyException(String message){  
        super(message);  
    }  
}  
  
public class Test {  
    public void display(int i) throws MyException{  
        if(i == 0){  
            throw new MyException("该值不能为0.......");  
        }  
        else{  
            System.out.println( i / 2);  
        }  
    }  
      
    public static void main(String[] args) {  
        Test test = new Test();  
        try {  
            test.display(0);  
            System.out.println("---------------------");  
        } catch (MyException e) {  
            e.printStackTrace();  
        }  
    }  
} 
------------------------------------------------------------------------------------
输出：
    com.xx.MyException:该值不能为0
        at com.xx.Test.display(Test.java:12)
```

####  什么是“异常链”

在捕获一个异常后，抛出另一个异常，并且希望把原始异常信息保留下来，这被称为**异常链**。

在设计模式中有一个叫做责任链模式，该模式是将多个对象链接成一条链，客户端的请求沿着这条链传递直到被接收、处理。同样Java异常机制也提供了这样一条链：==异常链==。  
我们知道每遇到一个异常信息，我们都需要进行try…catch,一个还好，如果出现多个异常呢？分类处理肯定会比较麻烦，那就一个Exception解决所有的异常吧。这样确实是可以，但是这样处理势必会导致后面的维护难度增加。最好的办法就是将这些异常信息封装，然后捕获我们的封装类即可。  
诚然在应用程序中，我们有时候不仅仅只需要封装异常，更需要传递。怎么传递？throws!！binge，正确！！但是如果仅仅只用throws抛出异常，那么你的封装类，怎么办？？  
我们有两种方式处理异常，一是throws抛出交给上级处理，二是try…catch做具体处理。但是这个与上面有什么关联呢？try…catch的catch块我们可以不需要做任何处理，仅仅只用throw这个关键字将我们封装异常信息主动抛出来。然后在通过关键字throws继续抛出该方法异常。它的上层也可以做这样的处理，以此类推就会产生一条由异常构成的异常链。

**通过使用异常链，我们可以提高代码的可理解性、系统的可维护性和友好性。**

同理，我们有时候在捕获一个异常后抛出另一个异常信息，并且希望将原始的异常信息也保持起来，这个时候也需要使用异常链。  
在异常链的使用中，throw抛出的是一个新的异常信息，这样势必会导致原有的异常信息丢失，如何保持？在Throwable及其子类中的构造器中都可以接受一个cause参数，该参数保存了原有的异常信息，通过getCause()就可以获取该原始异常信息。  
 语法：

```
public void test() throws XxxException{  
        try {  
            //do something:可能抛出异常信息的代码块  
        } catch (Exception e) {  
            throw new XxxException(e);  
        }  
    }  
```

示例：

```
public class Test {  
    public void f() throws MyException{  
         try {  
            FileReader reader = new FileReader("G:\\myfile\\struts.txt");    
             Scanner in = new Scanner(reader);    
             System.out.println(in.next());  
        } catch (FileNotFoundException e) {  
            //e 保存异常信息  
            throw new MyException("文件没有找到--01",e);  
        }    
    }  
      
    public void g() throws MyException{  
        try {  
            f();  
        } catch (MyException e) {  
            //e 保存异常信息  
            throw new MyException("文件没有找到--02",e);  
        }  
    }  
      
    public static void main(String[] args) {  
        Test t = new Test();  
        try {  
            t.g();  
        } catch (MyException e) {  
            e.printStackTrace();  
        }  
    }  
}  
```

 运行结果：

```
com.test9.MyException: 文件没有找到--02  
    at com.test9.Test.g(Test.java:31)  
    at com.test9.Test.main(Test.java:38)  
Caused by: com.test9.MyException: 文件没有找到--01  
    at com.test9.Test.f(Test.java:22)  
    at com.test9.Test.g(Test.java:28)  
    ... 1 more  
Caused by: java.io.FileNotFoundException: G:\myfile\struts.txt (系统找不到指定的路径。)  
    at java.io.FileInputStream.open(Native Method)  
    at java.io.FileInputStream.<init>(FileInputStream.java:106)  
    at java.io.FileInputStream.<init>(FileInputStream.java:66)  
    at java.io.FileReader.<init>(FileReader.java:41)  
    at com.test9.Test.f(Test.java:17)  
    ... 2 more  
```

如果在程序中,去掉e，也就是：throw new MyException("文件没有找到--02");  
那么异常信息就保存不了，运行结果如下：

```
com.test9.MyException: 文件没有找到--02  
    at com.test9.Test.g(Test.java:31)  
    at com.test9.Test.main(Test.java:38)  
```

####  finally与return

finally，除非System.exit(0);将JVM退出，否则永远都要执行finally域里的代码。  

```java
try{
    ...
    return;
}catch(Exception e){
    throw e;
}finally{
    System.out.print("finally");
    return;
}
-------------------------------------------------------------------------------------
输出：
    finally
```

#### 常见异常

| **ArrayIndexOutOfBoundsException** | **数组越界异常**     |
| ---------------------------------- | -------------------- |
| **IOException**                    | **输入流输出流异常** |
| **NullPointerException**           | **空指针异常**       |
| **SQLException**                   | **数据库语句异常**   |
| **ClassNotFoundException**         | **找不到类异常**     |

